Workbook

Sheet Article
C2: 아티클 번호 입력 →
B6: CONTAINER | C6: Planned Logistics Receiving(Date) | E6: PA | F6: ItemNo | G6: ItemName | H6: LatestRcvDate | I6: LatestQty | J6: CSM id | K6: SSD | L6: EDS | M6: TYPE
A7: =_xlfn.XLOOKUP(B7,SHP!D:D,SHP!CW:CW,"") | B7: =IF( _xlfn.XLOOKUP(J7,SHP!F:F,SHP!D:D,"")="", "", _xlfn.XLOOKUP(J7,SHP!F:F,SHP!D:D,"") ) | C7: =IF( _xlfn.XLOOKUP(J7,SHP!F:F,SHP!G:G,"")="", "", _xlfn.XLOOKUP(J7,SHP!F:F,SHP!G:G,"") ) | E7: {=IF( H2="", "", _xlfn._xlws.FILTER( _2__ROI_Daily_Update[], LEFT(_2__ROI_Daily_Update[ItemNo]&"",LEN(H2&""))=H2&"", "검색 결과 없음" ) )}
A8: =_xlfn.XLOOKUP(B8,SHP!D:D,SHP!CW:CW,"") | B8: =IF( _xlfn.XLOOKUP(J8,SHP!F:F,SHP!D:D,"")="", "", _xlfn.XLOOKUP(J8,SHP!F:F,SHP!D:D,"") ) | C8: =IF( _xlfn.XLOOKUP(J8,SHP!F:F,SHP!G:G,"")="", "", _xlfn.XLOOKUP(J8,SHP!F:F,SHP!G:G,"") )
A9: =_xlfn.XLOOKUP(B9,SHP!D:D,SHP!CW:CW,"") | B9: =IF( _xlfn.XLOOKUP(J9,SHP!F:F,SHP!D:D,"")="", "", _xlfn.XLOOKUP(J9,SHP!F:F,SHP!D:D,"") ) | C9: =IF( _xlfn.XLOOKUP(J9,SHP!F:F,SHP!G:G,"")="", "", _xlfn.XLOOKUP(J9,SHP!F:F,SHP!G:G,"") )
A10: =_xlfn.XLOOKUP(B10,SHP!D:D,SHP!CW:CW,"") | B10: =IF( _xlfn.XLOOKUP(J10,SHP!F:F,SHP!D:D,"")="", "", _xlfn.XLOOKUP(J10,SHP!F:F,SHP!D:D,"") ) | C10: =IF( _xlfn.XLOOKUP(J10,SHP!F:F,SHP!G:G,"")="", "", _xlfn.XLOOKUP(J10,SHP!F:F,SHP!G:G,"") )
A11: =_xlfn.XLOOKUP(B11,SHP!D:D,SHP!CW:CW,"") | B11: =IF( _xlfn.XLOOKUP(J11,SHP!F:F,SHP!D:D,"")="", "", _xlfn.XLOOKUP(J11,SHP!F:F,SHP!D:D,"") ) | C11: =IF( _xlfn.XLOOKUP(J11,SHP!F:F,SHP!G:G,"")="", "", _xlfn.XLOOKUP(J11,SHP!F:F,SHP!G:G,"") )
A12: =_xlfn.XLOOKUP(B12,SHP!D:D,SHP!CW:CW,"") | B12: =IF( _xlfn.XLOOKUP(J12,SHP!F:F,SHP!D:D,"")="", "", _xlfn.XLOOKUP(J12,SHP!F:F,SHP!D:D,"") ) | C12: =IF( _xlfn.XLOOKUP(J12,SHP!F:F,SHP!G:G,"")="", "", _xlfn.XLOOKUP(J12,SHP!F:F,SHP!G:G,"") )
A13: =_xlfn.XLOOKUP(B13,SHP!D:D,SHP!CW:CW,"") | B13: =IF( _xlfn.XLOOKUP(J13,SHP!F:F,SHP!D:D,"")="", "", _xlfn.XLOOKUP(J13,SHP!F:F,SHP!D:D,"") ) | C13: =IF( _xlfn.XLOOKUP(J13,SHP!F:F,SHP!G:G,"")="", "", _xlfn.XLOOKUP(J13,SHP!F:F,SHP!G:G,"") )
A14: =_xlfn.XLOOKUP(B14,SHP!D:D,SHP!CW:CW,"") | B14: =IF( _xlfn.XLOOKUP(J14,SHP!F:F,SHP!D:D,"")="", "", _xlfn.XLOOKUP(J14,SHP!F:F,SHP!D:D,"") ) | C14: =IF( _xlfn.XLOOKUP(J14,SHP!F:F,SHP!G:G,"")="", "", _xlfn.XLOOKUP(J14,SHP!F:F,SHP!G:G,"") )
A15: =_xlfn.XLOOKUP(B15,SHP!D:D,SHP!CW:CW,"") | B15: =IF( _xlfn.XLOOKUP(J15,SHP!F:F,SHP!D:D,"")="", "", _xlfn.XLOOKUP(J15,SHP!F:F,SHP!D:D,"") ) | C15: =IF( _xlfn.XLOOKUP(J15,SHP!F:F,SHP!G:G,"")="", "", _xlfn.XLOOKUP(J15,SHP!F:F,SHP!G:G,"") )
A16: =_xlfn.XLOOKUP(B16,SHP!D:D,SHP!CW:CW,"") | B16: =IF( _xlfn.XLOOKUP(J16,SHP!F:F,SHP!D:D,"")="", "", _xlfn.XLOOKUP(J16,SHP!F:F,SHP!D:D,"") ) | C16: =IF( _xlfn.XLOOKUP(J16,SHP!F:F,SHP!G:G,"")="", "", _xlfn.XLOOKUP(J16,SHP!F:F,SHP!G:G,"") )
A17: =_xlfn.XLOOKUP(B17,SHP!D:D,SHP!CW:CW,"") | B17: =IF( _xlfn.XLOOKUP(J17,SHP!F:F,SHP!D:D,"")="", "", _xlfn.XLOOKUP(J17,SHP!F:F,SHP!D:D,"") ) | C17: =IF( _xlfn.XLOOKUP(J17,SHP!F:F,SHP!G:G,"")="", "", _xlfn.XLOOKUP(J17,SHP!F:F,SHP!G:G,"") )
A18: =_xlfn.XLOOKUP(B18,SHP!D:D,SHP!CW:CW,"") | B18: =IF( _xlfn.XLOOKUP(J18,SHP!F:F,SHP!D:D,"")="", "", _xlfn.XLOOKUP(J18,SHP!F:F,SHP!D:D,"") ) | C18: =IF( _xlfn.XLOOKUP(J18,SHP!F:F,SHP!G:G,"")="", "", _xlfn.XLOOKUP(J18,SHP!F:F,SHP!G:G,"") )
A19: =_xlfn.XLOOKUP(B19,SHP!D:D,SHP!CW:CW,"") | B19: =IF( _xlfn.XLOOKUP(J19,SHP!F:F,SHP!D:D,"")="", "", _xlfn.XLOOKUP(J19,SHP!F:F,SHP!D:D,"") ) | C19: =IF( _xlfn.XLOOKUP(J19,SHP!F:F,SHP!G:G,"")="", "", _xlfn.XLOOKUP(J19,SHP!F:F,SHP!G:G,"") )
... A72: =_xlfn.XLOOKUP(B72,SHP!D:D,SHP!CW:CW,"") | B72: =IF( _xlfn.XLOOKUP(J72,SHP!F:F,SHP!D:D,"")="", "", _xlfn.XLOOKUP(J72,SHP!F:F,SHP!D:D,"") ) | C72: =IF( _xlfn.XLOOKUP(J72,SHP!F:F,SHP!G:G,"")="", "", _xlfn.XLOOKUP(J72,SHP!F:F,SHP!G:G,"") )
A73: =_xlfn.XLOOKUP(B73,SHP!D:D,SHP!CW:CW,"")
A74: =_xlfn.XLOOKUP(B74,SHP!D:D,SHP!CW:CW,"")
A75: =_xlfn.XLOOKUP(B75,SHP!D:D,SHP!CW:CW,"")
A76: =_xlfn.XLOOKUP(B76,SHP!D:D,SHP!CW:CW,"")
A77: =_xlfn.XLOOKUP(B77,SHP!D:D,SHP!CW:CW,"")
A78: =_xlfn.XLOOKUP(B78,SHP!D:D,SHP!CW:CW,"")
A79: =_xlfn.XLOOKUP(B79,SHP!D:D,SHP!CW:CW,"")
A80: =_xlfn.XLOOKUP(B80,SHP!D:D,SHP!CW:CW,"")
A81: =_xlfn.XLOOKUP(B81,SHP!D:D,SHP!CW:CW,"")
A82: =_xlfn.XLOOKUP(B82,SHP!D:D,SHP!CW:CW,"")
A83: =_xlfn.XLOOKUP(B83,SHP!D:D,SHP!CW:CW,"") -> 0
A84: =_xlfn.XLOOKUP(B84,SHP!D:D,SHP!CW:CW,"") -> 0
... A300: =_xlfn.XLOOKUP(B300,SHP!D:D,SHP!CW:CW,"")

Sheet ROI
A1: PA | B1: ItemNo | C1: ItemName | D1: LatestRcvDate | E1: LatestQty | F1: CSM id | G1: SSD | H1: EDS | I1: TYPE | J1: ItemNo1 | K1: GDGY
A2: 431 | B2: 90561119 | C2: STORKLINTA chest/4 drw 70x50x98 white AP | D2: 46286 | E2: 8 | F2: 22715SUPECIS74434 | G2: 20261001 | I2: DD | J2: 90561119 | K2: =_xlfn.XLOOKUP(_2__ROI_Daily_Update[[#This Row],[CSM id]],SHP!F:F,SHP!EE:EE,"-") -> 0
A3: 431 | B3: 50561116 | C3: STORKLINTA chest/3 drw 70x50x75 white AP | D3: 46286 | E3: 6 | F3: 22715SUPECIS74434 | G3: 20261001 | I3: DD | J3: 50561116 | K3: =_xlfn.XLOOKUP(_2__ROI_Daily_Update[[#This Row],[CSM id]],SHP!F:F,SHP!EE:EE,"-") -> 0
A4: 214 | B4: 60275685 | C4: OXBERG door 40x97 white AP CN | D4: 46286 | E4: 70 | F4: 22715SUPECIS74434 | G4: 20140801 | I4: DD | J4: 60275685 | K4: =_xlfn.XLOOKUP(_2__ROI_Daily_Update[[#This Row],[CSM id]],SHP!F:F,SHP!EE:EE,"-") -> 0
A5: 431 | B5: 90559282 | C5: STORKLINTA chest/6 drw 70x50x120 white AP | D5: 46286 | E5: 8 | F5: 22715SUPECIS74434 | G5: 20261001 | I5: DD | J5: 90559282 | K5: =_xlfn.XLOOKUP(_2__ROI_Daily_Update[[#This Row],[CSM id]],SHP!F:F,SHP!EE:EE,"-") -> 0
A6: 431 | B6: 80561247 | C6: STORKLINTA chest/6 drw 140x50x75 white AP | D6: 46286 | E6: 8 | F6: 22715SUPECIS74434 | G6: 20261001 | I6: DD | J6: 80561247 | K6: =_xlfn.XLOOKUP(_2__ROI_Daily_Update[[#This Row],[CSM id]],SHP!F:F,SHP!EE:EE,"-") -> 0
A7: 1821 | B7: 90321619 | C7: SKÅDIS pgbrd 76x56 white AP CN | D7: 46286 | E7: 30 | F7: 22715SUPECIS74434 | G7: 20180201 | I7: DD | J7: 90321619 | K7: =_xlfn.XLOOKUP(_2__ROI_Daily_Update[[#This Row],[CSM id]],SHP!F:F,SHP!EE:EE,"-") -> 0
A8: 1821 | B8: 90321619 | C8: SKÅDIS pgbrd 76x56 white AP CN | D8: 46287 | E8: 30 | F8: 22715SUPECIS74800 | G8: 20180201 | I8: DD | J8: 90321619 | K8: =_xlfn.XLOOKUP(_2__ROI_Daily_Update[[#This Row],[CSM id]],SHP!F:F,SHP!EE:EE,"-") -> 0
A9: 1821 | B9: 30320806 | C9: SKÅDIS pgbrd 56x56 white AP CN | D9: 46287 | E9: 30 | F9: 22715SUPECIS74800 | G9: 20180201 | I9: DD | J9: 30320806 | K9: =_xlfn.XLOOKUP(_2__ROI_Daily_Update[[#This Row],[CSM id]],SHP!F:F,SHP!EE:EE,"-") -> 0
A10: 431 | B10: 90559282 | C10: STORKLINTA chest/6 drw 70x50x120 white AP | D10: 46287 | E10: 24 | F10: 22715SUPECIS74800 | G10: 20261001 | I10: DD | J10: 90559282 | K10: =_xlfn.XLOOKUP(_2__ROI_Daily_Update[[#This Row],[CSM id]],SHP!F:F,SHP!EE:EE,"-") -> 0
A11: 217 | B11: 00483263 | C11: VIHALS cb w sliding drs 95x47x90 white AP | D11: 46287 | E11: 70 | F11: 22715SUPECIS74800 | G11: 20220701 | I11: DD | J11: 483263 | K11: =_xlfn.XLOOKUP(_2__ROI_Daily_Update[[#This Row],[CSM id]],SHP!F:F,SHP!EE:EE,"-") -> 0
A12: 431 | B12: 90561119 | C12: STORKLINTA chest/4 drw 70x50x98 white AP | D12: 46287 | E12: 48 | F12: 22715SUPECIS74800 | G12: 20261001 | I12: DD | J12: 90561119 | K12: =_xlfn.XLOOKUP(_2__ROI_Daily_Update[[#This Row],[CSM id]],SHP!F:F,SHP!EE:EE,"-") -> 0
A13: 431 | B13: 50561116 | C13: STORKLINTA chest/3 drw 70x50x75 white AP | D13: 46287 | E13: 12 | F13: 22715SUPECIS74800 | G13: 20261001 | I13: DD | J13: 50561116 | K13: =_xlfn.XLOOKUP(_2__ROI_Daily_Update[[#This Row],[CSM id]],SHP!F:F,SHP!EE:EE,"-") -> 0
... A25: 1551 | B25: 60279725 | C25: IKEA 365+ mug 24 cl clear glass AP JP | D25: 46288 | E25: 192 | F25: 258DT260824726627 | G25: 20150401 | I25: HF | J25: 60279725 | K25: =_xlfn.XLOOKUP(_2__ROI_Daily_Update[[#This Row],[CSM id]],SHP!F:F,SHP!EE:EE,"-") -> 0
A26: 1511 | B26: 60321079 | C26: UPPVISPAD plate 22 white AP JP | D26: 46295 | E26: 42 | F26: 294DT260902726408 | G26: 20200601 | H26: 46388 | I26: LF | J26: 60321079 | K26: =_xlfn.XLOOKUP(_2__ROI_Daily_Update[[#This Row],[CSM id]],SHP!F:F,SHP!EE:EE,"-") -> 0
A27: 1511 | B27: 60592419 | C27: STOCKHOLM 2025 plate 26 black 2-p AP | D27: 46295 | E27: 22 | F27: 294DT260902726408 | G27: 20250401 | I27: LF | J27: 60592419 | K27: =_xlfn.XLOOKUP(_2__ROI_Daily_Update[[#This Row],[CSM id]],SHP!F:F,SHP!EE:EE,"-") -> 0
A28: 1422 | B28: 80563430 | C28: MÅNÖGA scissors stainless steel/black AP | D28: 46295 | E28: 272 | F28: 319DT260902726409 | G28: 20240101 | I28: LF | J28: 80563430 | K28: =_xlfn.XLOOKUP(_2__ROI_Daily_Update[[#This Row],[CSM id]],SHP!F:F,SHP!EE:EE,"-") -> 0
A29: 1412 | B29: 70324553 | C29: SENSUELL frying pan 28 stainless steel/grey AP JP | D29: 46295 | E29: 24 | F29: 319DT260902726409 | G29: 20160801 | I29: LF | J29: 70324553 | K29: =_xlfn.XLOOKUP(_2__ROI_Daily_Update[[#This Row],[CSM id]],SHP!F:F,SHP!EE:EE,"-") -> 0
A30: 1511 | B30: 50636555 | C30: VARDAGEN side plate 22 white AP | D30: 46295 | E30: 72 | F30: 294DT260902726408 | G30: 20261001 | I30: LF | J30: 50636555 | K30: =_xlfn.XLOOKUP(_2__ROI_Daily_Update[[#This Row],[CSM id]],SHP!F:F,SHP!EE:EE,"-") -> 0
A31: 1412 | B31: 70580699 | C31: IKEA 365+ NN frying pan 20 stnls/non-stick AP | D31: 46295 | E31: 140 | F31: 319DT260902726409 | G31: 20240701 | I31: LF | J31: 70580699 | K31: =_xlfn.XLOOKUP(_2__ROI_Daily_Update[[#This Row],[CSM id]],SHP!F:F,SHP!EE:EE,"-") -> 0
A32: 1412 | B32: 70587177 | C32: PUCKELLAX frying pan 28 non-stick coating AP | D32: 46295 | E32: 72 | F32: 319DT260902726409 | G32: 20250101 | I32: LF | J32: 70587177 | K32: =_xlfn.XLOOKUP(_2__ROI_Daily_Update[[#This Row],[CSM id]],SHP!F:F,SHP!EE:EE,"-") -> 0
A33: 1424 | B33: 80313323 | C33: OSTBIT serv plate 42 bamboo AP CN | D33: 46295 | E33: 46 | F33: 319DT260902726409 | G33: 20160701 | I33: LF | J33: 80313323 | K33: =_xlfn.XLOOKUP(_2__ROI_Daily_Update[[#This Row],[CSM id]],SHP!F:F,SHP!EE:EE,"-") -> 0
A34: 1511 | B34: 60600424 | C34: FÄRGKLAR side plate 20 light blue AP | D34: 46295 | E34: 132 | F34: 319DT260902726409 | G34: 20260101 | I34: LF | J34: 60600424 | K34: =_xlfn.XLOOKUP(_2__ROI_Daily_Update[[#This Row],[CSM id]],SHP!F:F,SHP!EE:EE,"-") -> 0
A35: 1511 | B35: 60282997 | C35: IKEA 365+ bowl 9 rounded sides white 2-p AP JP | D35: 46295 | E35: 108 | F35: 294DT260902726408 | G35: 20150401 | I35: LF | J35: 60282997 | K35: =_xlfn.XLOOKUP(_2__ROI_Daily_Update[[#This Row],[CSM id]],SHP!F:F,SHP!EE:EE,"-") -> 0
A36: 1511 | B36: 50607807 | C36: DAGGASTER deep plate 19 dotted/light beige AP | D36: 46295 | E36: 240 | F36: 319DT260902726409 | G36: 20251001 | I36: LF | J36: 50607807 | K36: =_xlfn.XLOOKUP(_2__ROI_Daily_Update[[#This Row],[CSM id]],SHP!F:F,SHP!EE:EE,"-") -> 0
A37: 1511 | B37: 50600759 | C37: GLADELIG plate 20x13 grey AP | D37: 46295 | E37: 105 | F37: 319DT260902726409 | G37: 20250701 | I37: LF | J37: 50600759 | K37: =_xlfn.XLOOKUP(_2__ROI_Daily_Update[[#This Row],[CSM id]],SHP!F:F,SHP!EE:EE,"-") -> 0
A38: 1422 | B38: 70581482 | C38: VARDAGEN zester w handle 33 stnls steel/beech AP | D38: 46295 | E38: 112 | F38: 319DT260902726409 | G38: 20241001 | I38: LF | J38: 70581482 | K38: =_xlfn.XLOOKUP(_2__ROI_Daily_Update[[#This Row],[CSM id]],SHP!F:F,SHP!EE:EE,"-") -> 0
A39: 1633 | B39: 10638896 | C39: VINTERFINT 2026 bowl w lid 18 red/white AP | D39: 46295 | E39: 12 | F39: 319DT260902726409 | G39: 20261001 | H39: 46388 | I39: LF | J39: 10638896 | K39: =_xlfn.XLOOKUP(_2__ROI_Daily_Update[[#This Row],[CSM id]],SHP!F:F,SHP!EE:EE,"-") -> 0
A40: 1512 | B40: 00603091 | C40: PINNLILJA serv bowl s2 AP | D40: 46295 | E40: 108 | F40: 294DT260902726408 | G40: 20260701 | I40: LF | J40: 603091 | K40: =_xlfn.XLOOKUP(_2__ROI_Daily_Update[[#This Row],[CSM id]],SHP!F:F,SHP!EE:EE,"-") -> 0
A41: 1511 | B41: 30621220 | C41: KEJSERLIG NN bowl 10 mixed colours 3-p AP | D41: 46295 | E41: 108 | F41: 319DT260902726409 | G41: 20260401 | H41: 46569 | I41: LF | J41: 30621220 | K41: =_xlfn.XLOOKUP(_2__ROI_Daily_Update[[#This Row],[CSM id]],SHP!F:F,SHP!EE:EE,"-") -> 0
A42: 1431 | B42: 10419059 | C42: EKLATANT jar/lid 1.8 l clear glass/bamboo AP | D42: 46295 | E42: 126 | F42: 319DT260902726409 | G42: 20251001 | I42: LF | J42: 10419059 | K42: =_xlfn.XLOOKUP(_2__ROI_Daily_Update[[#This Row],[CSM id]],SHP!F:F,SHP!EE:EE,"-") -> 0
A43: 1633 | B43: 10632936 | C43: KUSTFYR 2026 tin w lid s3 pumpk-shpd mix col AP | D43: 46295 | E43: 48 | F43: 319DT260902726409 | G43: 20260801 | H43: 46388 | I43: LF | J43: 10632936 | K43: =_xlfn.XLOOKUP(_2__ROI_Daily_Update[[#This Row],[CSM id]],SHP!F:F,SHP!EE:EE,"-") -> 0
A44: 1541 | B44: 40642707 | C44: VINTERFINT 2026 paper napkin 33x33 st/gn/wh 30p AP | D44: 46295 | E44: 280 | F44: 294DT260902726408 | G44: 20261001 | H44: 46388 | I44: LF | J44: 40642707 | K44: =_xlfn.XLOOKUP(_2__ROI_Daily_Update[[#This Row],[CSM id]],SHP!F:F,SHP!EE:EE,"-") -> 0
A45: 1412 | B45: 90324552 | C45: SENSUELL frying pan 24 stainless steel/grey AP JP | D45: 46295 | E45: 12 | F45: 319DT260902726409 | G45: 20160801 | I45: LF | J45: 90324552 | K45: =_xlfn.XLOOKUP(_2__ROI_Daily_Update[[#This Row],[CSM id]],SHP!F:F,SHP!EE:EE,"-") -> 0
A46: 1422 | B46: 80422322 | C46: IKEA 365+ mandoline black AP | D46: 46295 | E46: 64 | F46: 319DT260902726409 | G46: 20191001 | I46: LF | J46: 80422322 | K46: =_xlfn.XLOOKUP(_2__ROI_Daily_Update[[#This Row],[CSM id]],SHP!F:F,SHP!EE:EE,"-") -> 0
A47: 1412 | B47: 80484254 | C47: IKEA 365+ N saute pan 24 stainless steel AP | D47: 46295 | E47: 12 | F47: 319DT260902726409 | G47: 20220101 | I47: LF | J47: 80484254 | K47: =_xlfn.XLOOKUP(_2__ROI_Daily_Update[[#This Row],[CSM id]],SHP!F:F,SHP!EE:EE,"-") -> 0
A48: 1511 | B48: 40609736 | C48: SILVERSIDA side plate 20 patterned/blue AP | D48: 46295 | E48: 144 | F48: 294DT260902726408 | G48: 20251001 | I48: LF | J48: 40609736 | K48: =_xlfn.XLOOKUP(_2__ROI_Daily_Update[[#This Row],[CSM id]],SHP!F:F,SHP!EE:EE,"-") -> 0
A49: 1511 | B49: 40631488 | C49: STRIMMIG plate 27 stoneware pale grey-green AP | D49: 46295 | E49: 36 | F49: 319DT260902726409 | G49: 20260701 | I49: LF | J49: 40631488 | K49: =_xlfn.XLOOKUP(_2__ROI_Daily_Update[[#This Row],[CSM id]],SHP!F:F,SHP!EE:EE,"-") -> 0
A50: 1412 | B50: 70609476 | C50: GULDÖRING frying pan 24 non-stick stnls/blkgrey AP | D50: 46295 | E50: 224 | F50: 319DT260902726409 | G50: 20260701 | I50: LF | J50: 70609476 | K50: =_xlfn.XLOOKUP(_2__ROI_Daily_Update[[#This Row],[CSM id]],SHP!F:F,SHP!EE:EE,"-") -> 0
A51: 1511 | B51: 50600434 | C51: FÄRGKLAR deep plate 23 light pink AP | D51: 46295 | E51: 60 | F51: 319DT260902726409 | G51: 20250701 | I51: LF | J51: 50600434 | K51: =_xlfn.XLOOKUP(_2__ROI_Daily_Update[[#This Row],[CSM id]],SHP!F:F,SHP!EE:EE,"-") -> 0
...

Sheet Data
A1: {=_xlfn.LET( _xlpm.src, SHP!A:AH, _xlpm.lastRow, MAX((SHP!A:AH<>"")*ROW(SHP!A:AH)), _xlfn.TAKE(_xlpm.src, _xlpm.lastRow) )} -> TYPE | B1: TYPE_1 | C1: BL | D1: Container NO. | E1: Lut Code | F1: Csm Id | G1: Planned Logistics Receiving(Date) | H1: Planned Logistics Receiving(Time) | I1: Cus. Date | J1: Customs Inspection Date | K1: Actual Arrival Date | L1: shipment ID | M1: Csm Stat | N1: Shp Id | O1: Shp Stat | P1: Shp CarContact | Q1: Shp DayCre | R1: Cnee Code | S1: Cnee Type | T1: Total Art Qty (pcs) | U1: Csm VolNetTot | V1: Csm VolGroTot | W1: Csm WeiGroTot | X1: Csm ArrDayPlan | Y1: ShpRou RecPldArrDate | Z1: LuTrL ActDepDate | AA1: Carrier Code | AB1: Carrier Name | AC1: Seal | AD1: Vessel Name | AE1: Voyage No | AF1: Start Cty | AG1: Start Type | AH1: Start Code
A2: DD | C2: MAEUIK0223295 | D2: TCNU5314437 | E2: C40HC | F2: 19720SUPECIS214232 | G2: 46316 | H2: 0.27083333 | I2: 46303 | J2: 0 | K2: 46303 | L2: 373-STO-S10000031673 | M2: 400 | N2: 012TSOS10000407873 | O2: 400 | P2: HEDXU | Q2: 46279 | R2: 726 | S2: STO | T2: 15061 | U2: 56.914439 | V2: 61.256584 | W2: 7562.76 | X2: 46304 | Y2: 46303 | Z2: 46292 | AA2: 31825 | AB2: MAERSK A/S | AC2: CN8689338 | AD2: MAERSK NANSHA | AE2: 638N | AF2: CN | AG2: PRT | AH2: CNNSA
A3: DD | B3: MILK RUN NOR | C3: MAEUIK0222834 | D3: MIEU4249438 | E3: C40HC | F3: 22715SUPECIS75024 | G3: 46316 | H3: 0.35416667 | I3: 46307 | J3: 0 | K3: 46305 | L3: 373-STO-S10000031661 | M3: 400 | N3: 037TSOS10000702465 | O3: 350 | P3: JIZHU80 | Q3: 46275 | R3: 726 | S3: STO | T3: 164 | U3: 5.067238 | V3: 5.435276 | W3: 1983.56 | X3: 46311 | Y3: 46305 | Z3: 0 | AA3: 31825 | AB3: MAERSK A/S | AC3: CN8245167 | AD3: MERATUS JIMBARAN | AE3: 638N | AF3: CN | AG3: PRT | AH3: CNSHA
A4: LF | B4: 0 | C4: MAEUIK0220641 | D4: MIEU4024977 | E4: C40HC | F4: 294DT260826726664 | G4: 46315 | H4: 0.27083333 | I4: 46302 | J4: 0 | K4: 46300 | L4: 373-STO-S10000031671 | M4: 400 | N4: 258DTS10000201064 | O4: 350 | P4: LARXU | Q4: 46260 | R4: 726 | S4: STO | T4: 3377 | U4: 7.235952 | V4: 7.84381039 | W4: 1509.796 | X4: 46299 | Y4: 46300 | Z4: 0 | AA4: 31825 | AB4: MAERSK A/S | AC4: CN7277998 | AD4: GSL ELEFTHERIA | AE4: 637N | AF4: CN | AG4: PRT | AH4: CNSHA
A5: LF | B5: 0 | C5: MAEUIK0220641 | D5: MIEU4024977 | E5: C40HC | F5: 319DT260826726665 | G5: 46315 | H5: 0.27083333 | I5: 46302 | J5: 0 | K5: 46300 | L5: 373-STO-S10000031671 | M5: 400 | N5: 258DTS10000201064 | O5: 350 | P5: LARXU | Q5: 46260 | R5: 726 | S5: STO | T5: 13562 | U5: 40.904855 | V5: 44.13954984 | W5: 9133.879 | X5: 46299 | Y5: 46300 | Z5: 0 | AA5: 31825 | AB5: MAERSK A/S | AC5: CN7277998 | AD5: GSL ELEFTHERIA | AE5: 637N | AF5: CN | AG5: PRT | AH5: CNSHA
A6: HF | B6: 0 | C6: MAEUIK0222603 | D6: CAJU5753527 | E6: C40HC | F6: 258DT260909726619 | G6: 46315 | H6: 0.625 | I6: 46307 | J6: 0 | K6: 46305 | L6: 373-STO-S10000031672 | M6: 400 | N6: 258DTS10000203144 | O6: 350 | P6: 0 | Q6: 46274 | R6: 726 | S6: STO | T6: 6927 | U6: 48.972276 | V6: 52.63371671 | W6: 6585.397 | X6: 46299 | Y6: 46305 | Z6: 0 | AA6: 31825 | AB6: MAERSK A/S | AC6: CN8245126 | AD6: MERATUS JIMBARAN | AE6: 638N | AF6: CN | AG6: PRT | AH6: CNSHA
A7: HF | B7: 0 | C7: MAEUIK0222603 | D7: CAJU5753527 | E7: C40HC | F7: 277DT260909726620 | G7: 46315 | H7: 0.625 | I7: 46307 | J7: 0 | K7: 46305 | L7: 373-STO-S10000031672 | M7: 400 | N7: 258DTS10000203144 | O7: 350 | P7: 0 | Q7: 46274 | R7: 726 | S7: STO | T7: 2602 | U7: 6.940198 | V7: 7.441753 | W7: 1068.502 | X7: 46299 | Y7: 46305 | Z7: 0 | AA7: 31825 | AB7: MAERSK A/S | AC7: CN8245126 | AD7: MERATUS JIMBARAN | AE7: 638N | AF7: CN | AG7: PRT | AH7: CNSHA
A8: DD | B8: MILK RUN NOR | C8: MAEUIK0222136 | D8: GATU8481853 | E8: C40HC | F8: 21072SUPECIS76085 | G8: 46314 | H8: 0.35416667 | I8: 46307 | J8: 0 | K8: 46304 | L8: 373-STO-S10000031632 | M8: 400 | N8: 037TSOS10000698570 | O8: 350 | P8: LINLI65 | Q8: 46271 | R8: 726 | S8: STO | T8: 156 | U8: 4.539972 | V8: 4.841639 | W8: 1999.62 | X8: 46293 | Y8: 46304 | Z8: 0 | AA8: 31825 | AB8: MAERSK A/S | AC8: CN8989674 | AD8: GJERTRUD MAERSK | AE8: 638E | AF8: CN | AG8: PRT | AH8: CNNGB
A9: LF | B9: 0 | C9: MAEUIK0221076 | D9: MIEU3937673 | E9: C40HC | F9: 294DT260828726913 | G9: 46314 | H9: 0.27083333 | I9: 46303 | J9: 0 | K9: 46300 | L9: 373-STO-S10000031638 | M9: 400 | N9: 258DTS10000201515 | O9: 350 | P9: LARXU | Q9: 46262 | R9: 726 | S9: STO | T9: 11249 | U9: 15.890792 | V9: 17.13080399 | W9: 3153.507 | X9: 46299 | Y9: 46300 | Z9: 0 | AA9: 31825 | AB9: MAERSK A/S | AC9: CN7277991 | AD9: GSL ELEFTHERIA | AE9: 637N | AF9: CN | AG9: PRT | AH9: CNSHA
A10: LF | B10: 0 | C10: MAEUIK0221076 | D10: MIEU3937673 | E10: C40HC | F10: 319DT260828726914 | G10: 46314 | H10: 0.27083333 | I10: 46303 | J10: 0 | K10: 46300 | L10: 373-STO-S10000031638 | M10: 400 | N10: 258DTS10000201515 | O10: 350 | P10: LARXU | Q10: 46262 | R10: 726 | S10: STO | T10: 10034 | U10: 32.237779 | V10: 34.78955881 | W10: 7090.924 | X10: 46299 | Y10: 46300 | Z10: 0 | AA10: 31825 | AB10: MAERSK A/S | AC10: CN7277991 | AD10: GSL ELEFTHERIA | AE10: 637N | AF10: CN | AG10: PRT | AH10: CNSHA
A11: DD | B11: MILK RUN NOR | C11: MAEUIK0221730 | D11: MIEU4055031 | E11: C40HC | F11: 21072SUPECIS75985 | G11: 46313 | H11: 0.35416667 | I11: 46307 | J11: 0 | K11: 46304 | L11: 373-STO-S10000031603 | M11: 400 | N11: 037TSOS10000696475 | O11: 350 | P11: LINLI65 | Q11: 46268 | R11: 726 | S11: STO | T11: 204 | U11: 5.917482 | V11: 6.312573 | W11: 2962.82 | X11: 46293 | Y11: 46304 | Z11: 0 | AA11: 31825 | AB11: MAERSK A/S | AC11: CN9083167 | AD11: GJERTRUD MAERSK | AE11: 638E | AF11: CN | AG11: PRT | AH11: CNNGB
A12: HF | B12: 0 | C12: MAEUIK0222031 | D12: MIEU4248386 | E12: C40HC | F12: 258DT260904726418 | G12: 46313 | H12: 0.26041667 | I12: 46307 | J12: 0 | K12: 46305 | L12: 373-STO-S10000031617 | M12: 400 | N12: 258DTS10000202574 | O12: 350 | P12: 0 | Q12: 46269 | R12: 726 | S12: STO | T12: 6394 | U12: 55.448337 | V12: 60.24409681 | W12: 10041.689 | X12: 46298 | Y12: 46305 | Z12: 0 | AA12: 31825 | AB12: MAERSK A/S | AC12: CN8245186 | AD12: MERATUS JIMBARAN | AE12: 638N | AF12: CN | AG12: PRT | AH12: CNSHA
A13: DD | B13: MILK RUN NOR | C13: PLISH7H50874 | D13: HLHU8363061 | E13: C40HC | F13: 21072SUPECIS76473 | G13: 46312 | H13: 0.35416667 | I13: 46303 | J13: 0 | K13: 46303 | L13: 373-STO-S10000031593 | M13: 400 | N13: 037TSOS10000709772 | O13: 300 | P13: LINLI65 | Q13: 46288 | R13: 726 | S13: STO | T13: 204 | U13: 5.768894 | V13: 6.136606 | W13: 2268.98 | X13: 46304 | Y13: 46302 | Z13: 0 | AA13: 33300 | AB13: LX PANTOS CO., LTD. | AC13: 123123 | AD13: SAWASDEE SIRIUS | AE13: 2626E | AF13: CN | AG13: PRT | AH13: CNNGB
A14: HF | B14: 0 | C14: MAEUIK0221456 | D14: MRKU5905253 | E14: C40HC | F14: 258DT260901726134 | G14: 46312 | H14: 0.26041667 | I14: 46302 | J14: 0 | K14: 46300 | L14: 373-STO-S10000031599 | M14: 400 | N14: 258DTS10000201885 | O14: 350 | P14: JEGAO9 | Q14: 46266 | R14: 726 | S14: STO | T14: 7206 | U14: 52.9611 | V14: 56.90923493 | W14: 10466.317 | X14: 46299 | Y14: 46300 | Z14: 0 | AA14: 31825 | AB14: MAERSK A/S | AC14: CN8117899 | AD14: GSL ELEFTHERIA | AE14: 637N | AF14: CN | AG14: PRT | AH14: CNSHA
A15: HF | B15: 0 | C15: MAEUIK0221456 | D15: MRKU5905253 | E15: C40HC | F15: 258DT260901726136 | G15: 46312 | H15: 0.26041667 | I15: 46302 | J15: 0 | K15: 46300 | L15: 373-STO-S10000031599 | M15: 400 | N15: 258DTS10000201885 | O15: 350 | P15: JEGAO9 | Q15: 46266 | R15: 726 | S15: STO | T15: 220 | U15: 2.79726 | V15: 2.985278 | W15: 824.622 | X15: 46299 | Y15: 46300 | Z15: 0 | AA15: 31825 | AB15: MAERSK A/S | AC15: CN8117899 | AD15: GSL ELEFTHERIA | AE15: 637N | AF15: CN | AG15: PRT | AH15: CNSHA
A16: HF | B16: 0 | C16: MAEUIK0221456 | D16: MRKU5905253 | E16: C40HC | F16: 277DT260901726137 | G16: 46312 | H16: 0.26041667 | I16: 46302 | J16: 0 | K16: 46300 | L16: 373-STO-S10000031599 | M16: 400 | N16: 258DTS10000201885 | O16: 350 | P16: JEGAO9 | Q16: 46266 | R16: 726 | S16: STO | T16: 128 | U16: 0.524288 | V16: 0.556875 | W16: 37.76 | X16: 46299 | Y16: 46300 | Z16: 0 | AA16: 31825 | AB16: MAERSK A/S | AC16: CN8117899 | AD16: GSL ELEFTHERIA | AE16: 637N | AF16: CN | AG16: PRT | AH16: CNSHA
A17: DD | B17: MILK RUN NOR | C17: MAEUIK0222640 | D17: MIEU4026136 | E17: C40HC | F17: 22715SUPECIS74434 | G17: 46312 | H17: 0.35416667 | I17: 46302 | J17: 0 | K17: 46300 | L17: 373-STO-S10000031592 | M17: 400 | N17: 037TSOS10000701591 | O17: 350 | P17: HEDXU | Q17: 46274 | R17: 726 | S17: STO | T17: 130 | U17: 5.51538 | V17: 5.913997 | W17: 2074.79 | X17: 46286 | Y17: 46300 | Z17: 0 | AA17: 31825 | AB17: MAERSK A/S | AC17: CN8118336 | AD17: GSL ELEFTHERIA | AE17: 637N | AF17: CN | AG17: PRT | AH17: CNSHA
A18: LF | B18: 0 | C18: MAEUIK0220633 | D18: MIEU4026408 | E18: C40HC | F18: 294DT260826726667 | G18: 46311 | H18: 0.27083333 | I18: 46302 | J18: 0 | K18: 46300 | L18: 373-STO-S10000031572 | M18: 400 | N18: 258DTS10000201056 | O18: 350 | P18: LARXU | Q18: 46260 | R18: 726 | S18: STO | T18: 1324 | U18: 5.167979 | V18: 5.57277518 | W18: 1073.011 | X18: 46299 | Y18: 46300 | Z18: 0 | AA18: 31825 | AB18: MAERSK A/S | AC18: CN7277908 | AD18: GSL ELEFTHERIA | AE18: 637N | AF18: CN | AG18: PRT | AH18: CNSHA
A19: LF | B19: 0 | C19: MAEUIK0220633 | D19: MIEU4026408 | E19: C40HC | F19: 319DT260826726668 | G19: 46311 | H19: 0.27083333 | I19: 46302 | J19: 0 | K19: 46300 | L19: 373-STO-S10000031572 | M19: 400 | N19: 258DTS10000201056 | O19: 350 | P19: LARXU | Q19: 46260 | R19: 726 | S19: STO | T19: 12744 | U19: 43.098395 | V19: 46.33617804 | W19: 7481.412 | X19: 46299 | Y19: 46300 | Z19: 0 | AA19: 31825 | AB19: MAERSK A/S | AC19: CN7277908 | AD19: GSL ELEFTHERIA | AE19: 637N | AF19: CN | AG19: PRT | AH19: CNSHA
A20: DD | B20: MILK RUN NOR | C20: MAEUIK0222641 | D20: MIEU4250531 | E20: C40HC | F20: 22715SUPECIS74800 | G20: 46311 | H20: 0.35416667 | I20: 46301 | J20: 0 | K20: 46300 | L20: 373-STO-S10000031558 | M20: 400 | N20: 037TSOS10000701589 | O20: 350 | P20: HEDXU | Q20: 46274 | R20: 726 | S20: STO | T20: 284 | U20: 18.975908 | V20: 20.261386 | W20: 8158.02 | X20: 46287 | Y20: 46300 | Z20: 0 | AA20: 31825 | AB20: MAERSK A/S | AC20: CN8117812 | AD20: GSL ELEFTHERIA | AE20: 637N | AF20: CN | AG20: PRT | AH20: CNSHA
A21: DD | B21: MILK RUN NOR | C21: MAEUIK0220980 | D21: CAAU5980289 | E21: C40HC | F21: 21072SUPECIS75793 | G21: 46310 | H21: 0.35416667 | I21: 46302 | J21: 46301 | K21: 46298 | L21: 373-STO-S10000031553 | M21: 400 | N21: 037TSOS10000692070 | O21: 350 | P21: LINLI65 | Q21: 46261 | R21: 726 | S21: STO | T21: 195 | U21: 6.568349 | V21: 6.98245 | W21: 2702.47 | X21: 46286 | Y21: 46298 | Z21: 0 | AA21: 31825 | AB21: MAERSK A/S | AC21: CN6570542 | AD21: MUNDRA EXPRESS | AE21: 637E | AF21: CN | AG21: PRT | AH21: CNNGB
A22: HF | B22: F/C | C22: MAEUIK0220276 | D22: MRSU2805377 | E22: C40HC | F22: 258DT260824726627 | G22: 46310 | H22: 0.27083333 | I22: 46302 | J22: 0 | K22: 46285 | L22: 373-STO-S10000031571 | M22: 400 | N22: 258DTS10000200778 | O22: 350 | P22: 0 | Q22: 46258 | R22: 726 | S22: STO | T22: 25043 | U22: 46.062759 | V22: 49.8495584 | W22: 8479.826 | X22: 46271 | Y22: 46285 | Z22: 0 | AA22: 31825 | AB22: MAERSK A/S | AC22: CN4909050 | AD22: XIN BIN ZHOU | AE22: 635N | AF22: CN | AG22: PRT | AH22: CNSHA
A23: HF | B23: F/C | C23: MAEUIK0220276 | D23: MRSU2805377 | E23: C40HC | F23: 277DT260824726628 | G23: 46310 | H23: 0.27083333 | I23: 46302 | J23: 0 | K23: 46285 | L23: 373-STO-S10000031571 | M23: 400 | N23: 258DTS10000200778 | O23: 350 | P23: 0 | Q23: 46258 | R23: 726 | S23: STO | T23: 7208 | U23: 8.71888 | V23: 9.364472 | W23: 1703.984 | X23: 46271 | Y23: 46285 | Z23: 0 | AA23: 31825 | AB23: MAERSK A/S | AC23: CN4909050 | AD23: XIN BIN ZHOU | AE23: 635N | AF23: CN | AG23: PRT | AH23: CNSHA
A24: HF | B24: 0 | C24: MAEUIK0222039 | D24: MRKU4820043 | E24: C40HC | F24: 258DT260904726357 | G24: 46309 | H24: 0.27083333 | I24: 46302 | J24: 0 | K24: 46300 | L24: 373-STO-S10000031533 | M24: 400 | N24: 258DTS10000202591 | O24: 350 | P24: 0 | Q24: 46269 | R24: 726 | S24: STO | T24: 7443 | U24: 51.132604 | V24: 54.87575878 | W24: 5875.985 | X24: 46299 | Y24: 46300 | Z24: 0 | AA24: 31825 | AB24: MAERSK A/S | AC24: CN8163314 | AD24: GSL ELEFTHERIA | AE24: 637N | AF24: CN | AG24: PRT | AH24: CNSHA
A25: HF | B25: 0 | C25: MAEUIK0222039 | D25: MRKU4820043 | E25: C40HC | F25: 277DT260904726358 | G25: 46309 | H25: 0.27083333 | I25: 46302 | J25: 0 | K25: 46300 | L25: 373-STO-S10000031533 | M25: 400 | N25: 258DTS10000202591 | O25: 350 | P25: 0 | Q25: 46269 | R25: 726 | S25: STO | T25: 247 | U25: 4.413674 | V25: 4.713329 | W25: 892.138 | X25: 46299 | Y25: 46300 | Z25: 0 | AA25: 31825 | AB25: MAERSK A/S | AC25: CN8163314 | AD25: GSL ELEFTHERIA | AE25: 637N | AF25: CN | AG25: PRT | AH25: CNSHA
A26: DD | B26: MILK RUN NOR | C26: MAEUIK0220495 | D26: MIEU4025274 | E26: C40HC | F26: 22715SUPECIS74601 | G26: 46309 | H26: 0.35416667 | I26: 46302 | J26: 0 | K26: 46300 | L26: 373-STO-S10000031511 | M26: 400 | N26: 037TSOS10000689650 | O26: 350 | P26: JIZHU80 | Q26: 46259 | R26: 726 | S26: STO | T26: 250 | U26: 13.652022 | V26: 14.587563 | W26: 5544.26 | X26: 46299 | Y26: 46300 | Z26: 0 | AA26: 31825 | AB26: MAERSK A/S | AC26: CN8118384 | AD26: GSL ELEFTHERIA | AE26: 637N | AF26: CN | AG26: PRT | AH26: CNSHA
A27: LF | B27: F/C | C27: MAEUIK0219223 | D27: MRSU0374959 | E27: C20DV | F27: 294DT260817726679 | G27: 46308 | H27: 0.27083333 | I27: 46297 | J27: 0 | K27: 46275 | L27: 373-STO-S10000031532 | M27: 400 | N27: 258DTS10000199632 | O27: 350 | P27: LARXU | Q27: 46251 | R27: 726 | S27: STO | T27: 10984 | U27: 7.940101 | V27: 8.60600785 | W27: 2156.211 | X27: 46268 | Y27: 46266 | Z27: 0 | AA27: 31825 | AB27: MAERSK A/S | AC27: CN9769825 | AD27: MERATUS JIMBARAN | AE27: 634N | AF27: CN | AG27: PRT | AH27: CNSHA
A28: LF | B28: F/C | C28: MAEUIK0219223 | D28: MRSU0374959 | E28: C20DV | F28: 319DT260817726680 | G28: 46308 | H28: 0.27083333 | I28: 46297 | J28: 0 | K28: 46275 | L28: 373-STO-S10000031532 | M28: 400 | N28: 258DTS10000199632 | O28: 350 | P28: LARXU | Q28: 46251 | R28: 726 | S28: STO | T28: 10401 | U28: 13.3342 | V28: 14.41738818 | W28: 2848.716 | X28: 46268 | Y28: 46266 | Z28: 0 | AA28: 31825 | AB28: MAERSK A/S | AC28: CN9769825 | AD28: MERATUS JIMBARAN | AE28: 634N | AF28: CN | AG28: PRT | AH28: CNSHA
A29: DD | B29: MILK RUN NOR | C29: MAEUIK0218541 | D29: MRSU8891731 | E29: C40HC | F29: 19369SUPVAN00068365 | G29: 46307 | H29: 0.35416667 | I29: 46301 | J29: 0 | K29: 46298 | L29: 373-STO-S10000031503 | M29: 400 | N29: 037TSOS10000679195 | O29: 350 | P29: ANLIU52 | Q29: 46246 | R29: 726 | S29: STO | T29: 130 | U29: 10.64271 | V29: 12.409665 | W29: 1146.74 | X29: 46293 | Y29: 46298 | Z29: 0 | AA29: 31825 | AB29: MAERSK A/S | AC29: CN6565368 | AD29: DUMMY BARGE | AE29: 1234 | AF29: CN | AG29: PRT | AH29: CNZPU
A30: HF | B30: 0 | C30: MAEUIK0221074 | D30: MIEU4007795 | E30: C40HC | F30: 258DT260828726987 | G30: 46307 | H30: 0.27083333 | I30: 46301 | J30: 0 | K30: 46300 | L30: 373-STO-S10000031531 | M30: 400 | N30: 258DTS10000201496 | O30: 350 | P30: 0 | Q30: 46262 | R30: 726 | S30: STO | T30: 6106 | U30: 50.572844 | V30: 54.43206636 | W30: 10984.606 | X30: 46288 | Y30: 46300 | Z30: 0 | AA30: 31825 | AB30: MAERSK A/S | AC30: CN7995161 | AD30: GSL ELEFTHERIA | AE30: 637N | AF30: CN | AG30: PRT | AH30: CNSHA
A31: HF | B31: 0 | C31: MAEUIK0221074 | D31: MIEU4007795 | E31: C40HC | F31: 277DT260828726988 | G31: 46307 | H31: 0.27083333 | I31: 46301 | J31: 0 | K31: 46300 | L31: 373-STO-S10000031531 | M31: 400 | N31: 258DTS10000201496 | O31: 350 | P31: 0 | Q31: 46262 | R31: 726 | S31: STO | T31: 2022 | U31: 5.032128 | V31: 5.433269 | W31: 747.58 | X31: 46288 | Y31: 46300 | Z31: 0 | AA31: 31825 | AB31: MAERSK A/S | AC31: CN7995161 | AD31: GSL ELEFTHERIA | AE31: 637N | AF31: CN | AG31: PRT | AH31: CNSHA
A32: DD | B32: MILK RUN NOR | C32: MAEUIK0220583 | D32: MRSU6552180 | E32: C40HC | F32: 21072SUPECIS75715 | G32: 46306 | H32: 0.35416667 | I32: 46301 | J32: 0 | K32: 46298 | L32: 373-STO-S10000031497 | M32: 400 | N32: 037TSOS10000690205 | O32: 300 | P32: LINLI65 | Q32: 46259 | R32: 726 | S32: STO | T32: 115 | U32: 5.441181 | V32: 5.792897 | W32: 2319.18 | X32: 46286 | Y32: 46298 | Z32: 0 | AA32: 31825 | AB32: MAERSK A/S | AC32: CN6555120 | AD32: MUNDRA EXPRESS | AE32: 637E | AF32: CN | AG32: PRT | AH32: CNNGB
A33: DD | C33: MAEUIK0221100 | D33: UETU2059170 | E33: C20DV | F33: 17596SUPECIS42925 | G33: 46306 | H33: 0.26041667 | I33: 46297 | J33: 0 | K33: 46297 | L33: 373-STO-S10000031466 | M33: 400 | N33: 041TSOS10000278373 | O33: 350 | P33: ELZHE | Q33: 46262 | R33: 726 | S33: STO | T33: 3076 | U33: 25.362248 | V33: 26.974425 | W33: 1470.41 | X33: 46290 | Y33: 46297 | Z33: 0 | AA33: 31825 | AB33: MAERSK A/S | AC33: ID1208780 | AD33: SKY PEACE | AE33: 635N | AF33: ID | AG33: PRT | AH33: IDJKT
A34: DD | B34: MILK RUN NOR | C34: OOLU2173640490 | D34: CSNU7283900 | E34: C40HC | F34: 23273SUP3644956 | G34: 46306 | H34: 0.35416667 | I34: 46301 | J34: 0 | K34: 46300 | L34: 373-STO-S10000031498 | M34: 400 | N34: 030TSOS10000134256 | O34: 350 | P34: JEGAO9 | Q34: 46261 | R34: 726 | S34: STO | T34: 12 | U34: 2.030178 | V34: 2.119852 | W34: 279.606 | X34: 46276 | Y34: 46299 | Z34: 0 | AA34: 30105 | AB34: ORIENT OVERSEAS CONTAINER LINE LTD. | AC34: OOLLGT8733 | AD34: OOCL MALAYSIA | AE34: 073W | AF34: CN | AG34: PRT | AH34: CNTXG
A35: DD | B35: MILK RUN NOR | C35: HLCUTS12609CESE3 | D35: HAMU4368269 | E35: C40HC | F35: 23273SUP3647962 | G35: 46305 | H35: 0.35416667 | I35: 46302 | J35: 0 | K35: 46300 | L35: 373-STO-S10000031492 | M35: 400 | N35: 030TSOS10000136019 | O35: 400 | P35: JEGAO9 | Q35: 46274 | R35: 726 | S35: STO | T35: 42 | U35: 4.092924 | V35: 4.302985 | W35: 444.33 | X35: 46313 | Y35: 46301 | Z35: 46292 | AA35: 31363 | AB35: HAPAG LLOYD AG | AC35: HLK7232702 | AD35: MAERSK CAMDEN | AE35: 639E | AF35: CN | AG35: PRT | AH35: CNTXG
A36: DD | B36: MILK RUN NOR | C36: OOLU2173978340 | D36: OOLU9923069 | E36: C40HC | F36: 23273SUP3646704 | G36: 46305 | H36: 0.35416667 | I36: 46301 | J36: 0 | K36: 46300 | L36: 373-STO-S10000031493 | M36: 400 | N36: 030TSOS10000135318 | O36: 350 | P36: JEGAO9 | Q36: 46269 | R36: 726 | S36: STO | T36: 12 | U36: 2.13408 | V36: 2.227652 | W36: 217.98 | X36: 46301 | Y36: 46299 | Z36: 0 | AA36: 30105 | AB36: ORIENT OVERSEAS CONTAINER LINE LTD. | AC36: OOLLGT8613 | AD36: OOCL MALAYSIA | AE36: 073W | AF36: CN | AG36: PRT | AH36: CNTXG
A37: DD | C37: MAEUIK0219274 | D37: MRKU9138463 | E37: C20DV | F37: 17596SUPECIS42821 | G37: 46305 | H37: 0.26041667 | I37: 46297 | J37: 0 | K37: 46297 | L37: 373-STO-S10000031465 | M37: 400 | N37: 041TSOS10000275113 | O37: 300 | P37: 0 | Q37: 46251 | R37: 726 | S37: STO | T37: 10276 | U37: 25.274728 | V37: 26.85891 | W37: 1417.92 | X37: 46290 | Y37: 46297 | Z37: 0 | AA37: 31825 | AB37: MAERSK A/S | AC37: ID1204857 | AD37: SKY PEACE | AE37: 635N | AF37: ID | AG37: PRT | AH37: IDJKT
A38: DD | B38: MILK RUN NOR | C38: MAEUIK0221175 | D38: MRSU9544784 | E38: C40HC | F38: 21072SUPECIS75824 | G38: 46304 | H38: 0.35416667 | I38: 46301 | J38: 0 | K38: 46298 | L38: 373-STO-S10000031446 | M38: 400 | N38: 037TSOS10000692821 | O38: 300 | P38: LINLI65 | Q38: 46262 | R38: 726 | S38: STO | T38: 282 | U38: 7.554486 | V38: 8.050364 | W38: 3097.99 | X38: 46286 | Y38: 46298 | Z38: 0 | AA38: 31825 | AB38: MAERSK A/S | AC38: CN6570450 | AD38: MUNDRA EXPRESS | AE38: 637E | AF38: CN | AG38: PRT | AH38: CNNGB
A39: HF | B39: F/C | C39: MAEUIK0219823 | D39: TCKU7855708 | E39: C40HC | F39: 258DT260820726495 | G39: 46304 | H39: 0.26041667 | I39: 46296 | J39: 0 | K39: 46275 | L39: 373-STO-S10000031430 | M39: 400 | N39: 258DTS10000200289 | O39: 350 | P39: 0 | Q39: 46254 | R39: 726 | S39: STO | T39: 8563 | U39: 21.731729 | V39: 23.46848301 | W39: 3714.406 | X39: 46268 | Y39: 46266 | Z39: 0 | AA39: 31825 | AB39: MAERSK A/S | AC39: CN7971754 | AD39: MERATUS JIMBARAN | AE39: 634N | AF39: CN | AG39: PRT | AH39: CNSHA
A40: HF | B40: F/C | C40: MAEUIK0219823 | D40: TCKU7855708 | E40: C40HC | F40: 277DT260820726496 | G40: 46304 | H40: 0.26041667 | I40: 46296 | J40: 0 | K40: 46275 | L40: 373-STO-S10000031430 | M40: 400 | N40: 258DTS10000200289 | O40: 350 | P40: 0 | Q40: 46254 | R40: 726 | S40: STO | T40: 29965 | U40: 33.504735 | V40: 36.258891 | W40: 9167.487 | X40: 46268 | Y40: 46266 | Z40: 0 | AA40: 31825 | AB40: MAERSK A/S | AC40: CN7971754 | AD40: MERATUS JIMBARAN | AE40: 634N | AF40: CN | AG40: PRT | AH40: CNSHA
...

Sheet SHP
A1: TYPE | B1: TYPE_1 | C1: BL | D1: Container NO. | E1: Lut Code | F1: Csm Id | G1: Planned Logistics Receiving(Date) | H1: Planned Logistics Receiving(Time) | I1: Cus. Date | J1: Customs Inspection Date | K1: Actual Arrival Date | L1: shipment ID | M1: Csm Stat | N1: Shp Id | O1: Shp Stat | P1: Shp CarContact | Q1: Shp DayCre | R1: Cnee Code | S1: Cnee Type | T1: Total Art Qty (pcs) | U1: Csm VolNetTot | V1: Csm VolGroTot | W1: Csm WeiGroTot | X1: Csm ArrDayPlan | Y1: ShpRou RecPldArrDate | Z1: LuTrL ActDepDate | AA1: Carrier Code | AB1: Carrier Name | AC1: Seal | AD1: Vessel Name | AE1: Voyage No | AF1: Start Cty | AG1: Start Type | AH1: Start Code | AI1: End Cty | AJ1: End Code | AK1: End TG:AEype | AL1: Incoterms | AM1: CGS Declaration No. | AN1: BL receiving | AO1: RECEIPTED BY CUSTOMS | AP1: BONDED WAREHOUSE | AQ1: SPLIT, LOCATION | AR1: Customs broker COMMENT | AS1: Damage Notice (MS bonded warehouse) | AT1: DEM exp date (ATA+14) | AU1: expiration date from Busan Port (Cus. Date+75days) | AV1: expiration date from INCHEON Port (Cus. Date+15days) | AW1: Inland Carrier | AX1: D-day Earliest | AY1: D-day Lasted | AZ1: DD best date | BA1: Actual Unloading | BB1: D | BC1: TYPE_2 | BD1: TYPE_3 | BE1: BL_4 | BF1: Container NO._5 | BG1: Lut Code_6 | BH1: POA Month | BI1: Floor_CSM | BJ1: Column62 | BK1: LT3.3 OT Early | BL1: LT3.3 OT Late | BM1: OTD Status | BN1: Causing party | BO1: Column67 | BP1: Column68 | BQ1: Column69 | BR1: Column70 | BS1: Column71 | BT1: Column72 | BU1: Column73 | BV1: Column74 | BW1: Column75 | BX1: Column76 | BY1: Column77 | BZ1: Column78 | CA1: Column79 | CB1: Column80 | CC1: Column81 | CD1: Column82 | CE1: Column83 | CF1: Column84 | CG1: Column85 | CH1: Column86 | CI1: Column87 | CJ1: Column88 | CK1: Column89 | CL1: Column90 | CM1: Column91 | CN1: Column92 | CO1: Column93 | CP1: Column94 | CQ1: Column95 | CR1: Column96 | CS1: Column97 | CT1: Column98 | CU1: Column99 | CV1: Column100 | CW1: Column101
A2: DD | C2: MAEUIK0223295 | D2: TCNU5314437 | E2: C40HC | F2: 19720SUPECIS214232 | G2: 46316 | H2: 0.27083333 | I2: 46303 | K2: 46303 | L2: 373-STO-S10000031673 | M2: 400 | N2: 012TSOS10000407873 | O2: 400 | P2: HEDXU | Q2: 46279 | R2: 726 | S2: STO | T2: 15061 | U2: 56.914439 | V2: 61.256584 | W2: 7562.76 | X2: 46304 | Y2: 46303 | Z2: 46292 | AA2: 31825 | AB2: MAERSK A/S | AC2: CN8689338 | AD2: MAERSK NANSHA | AE2: 638N | AF2: CN | AG2: PRT | AH2: CNNSA | AI2: KR | AJ2: KRPUS | AK2: PRT | AM2: INVMAEUIK0223295 | AO2: 46302 | AQ2: 부산신항만(주)자유무역지역 | AT2: 46316 | AU2: 46348 | AW2: HANJIN | BC2: DD | BE2: MAEUIK0223295 | BF2: TCNU5314437 | BG2: C40HC | CW2: {=IFERROR(_xlfn.IFS(H2=TIME(7,0,0),"GY",H2=TIME(7,30,0),"GY",H2=TIME(9,0,0),"GY",H2=TIME(15,0,0),"GY",H2=TIME(8,30,0),"GY",H2=TIME(5,30,0),"GY",H2=TIME(6,0,0),"GD",H2=TIME(6,30,0),"GD",H2=TIME(8,0,0),"GY",H2=TIME(6,15,0),"GD"),"")} -> GD
A3: DD | B3: MILK RUN NOR | C3: MAEUIK0222834 | D3: MIEU4249438 | E3: C40HC | F3: 22715SUPECIS75024 | G3: 46316 | H3: 0.35416667 | I3: 46307 | K3: 46305 | L3: 373-STO-S10000031661 | M3: 400 | N3: 037TSOS10000702465 | O3: 350 | P3: JIZHU80 | Q3: 46275 | R3: 726 | S3: STO | T3: 164 | U3: 5.067238 | V3: 5.435276 | W3: 1983.56 | X3: 46311 | Y3: 46305 | AA3: 31825 | AB3: MAERSK A/S | AC3: CN8245167 | AD3: MERATUS JIMBARAN | AE3: 638N | AF3: CN | AG3: PRT | AH3: CNSHA | AI3: KR | AJ3: KRINC | AK3: PRT | AM3: INVMAEUIK0222834 | AO3: 46307 | AQ3: 한진인천컨테이너터미널(주) | AS3: 신한 | AT3: 46319 | AV3: 46322 | AW3: HANJIN | BC3: DD | BD3: MILK RUN NOR | BE3: MAEUIK0222834 | BF3: MIEU4249438 | BG3: C40HC | CW3: {=IFERROR(_xlfn.IFS(H3=TIME(7,0,0),"GY",H3=TIME(7,30,0),"GY",H3=TIME(9,0,0),"GY",H3=TIME(15,0,0),"GY",H3=TIME(8,30,0),"GY",H3=TIME(5,30,0),"GY",H3=TIME(6,0,0),"GD",H3=TIME(6,30,0),"GD",H3=TIME(8,0,0),"GY",H3=TIME(6,15,0),"GD"),"")} -> GY
A4: LF | C4: MAEUIK0220641 | D4: MIEU4024977 | E4: C40HC | F4: 294DT260826726664 | G4: 46315 | H4: 0.27083333 | I4: 46302 | K4: 46300 | L4: 373-STO-S10000031671 | M4: 400 | N4: 258DTS10000201064 | O4: 350 | P4: LARXU | Q4: 46260 | R4: 726 | S4: STO | T4: 3377 | U4: 7.235952 | V4: 7.84381039 | W4: 1509.796 | X4: 46299 | Y4: 46300 | AA4: 31825 | AB4: MAERSK A/S | AC4: CN7277998 | AD4: GSL ELEFTHERIA | AE4: 637N | AF4: CN | AG4: PRT | AH4: CNSHA | AI4: KR | AJ4: KRINC | AK4: PRT | AL4: 한진 | AM4: INVMAEUIK0220641 | AO4: 46302 | AQ4: 한진인천컨테이너터미널(주) | AS4: 신한 | AT4: 46314 | AW4: HANJIN | BC4: LF | BE4: MAEUIK0220641 | BF4: MIEU4024977 | BG4: C40HC | CW4: {=IFERROR(_xlfn.IFS(H4=TIME(7,0,0),"GY",H4=TIME(7,30,0),"GY",H4=TIME(9,0,0),"GY",H4=TIME(15,0,0),"GY",H4=TIME(8,30,0),"GY",H4=TIME(5,30,0),"GY",H4=TIME(6,0,0),"GD",H4=TIME(6,30,0),"GD",H4=TIME(8,0,0),"GY",H4=TIME(6,15,0),"GD"),"")} -> GD
A5: LF | C5: MAEUIK0220641 | D5: MIEU4024977 | E5: C40HC | F5: 319DT260826726665 | G5: 46315 | H5: 0.27083333 | I5: 46302 | K5: 46300 | L5: 373-STO-S10000031671 | M5: 400 | N5: 258DTS10000201064 | O5: 350 | P5: LARXU | Q5: 46260 | R5: 726 | S5: STO | T5: 13562 | U5: 40.904855 | V5: 44.13954984 | W5: 9133.879 | X5: 46299 | Y5: 46300 | AA5: 31825 | AB5: MAERSK A/S | AC5: CN7277998 | AD5: GSL ELEFTHERIA | AE5: 637N | AF5: CN | AG5: PRT | AH5: CNSHA | AI5: KR | AJ5: KRINC | AK5: PRT | AL5: 한진 | AM5: INVMAEUIK0220641 | AO5: 46302 | AQ5: 한진인천컨테이너터미널(주) | AS5: 신한 | AT5: 46314 | AW5: HANJIN | BC5: LF | BE5: MAEUIK0220641 | BF5: MIEU4024977 | BG5: C40HC | CW5: {=IFERROR(_xlfn.IFS(H5=TIME(7,0,0),"GY",H5=TIME(7,30,0),"GY",H5=TIME(9,0,0),"GY",H5=TIME(15,0,0),"GY",H5=TIME(8,30,0),"GY",H5=TIME(5,30,0),"GY",H5=TIME(6,0,0),"GD",H5=TIME(6,30,0),"GD",H5=TIME(8,0,0),"GY",H5=TIME(6,15,0),"GD"),"")} -> GD
A6: HF | C6: MAEUIK0222603 | D6: CAJU5753527 | E6: C40HC | F6: 258DT260909726619 | G6: 46315 | H6: 0.625 | I6: 46307 | K6: 46305 | L6: 373-STO-S10000031672 | M6: 400 | N6: 258DTS10000203144 | O6: 350 | Q6: 46274 | R6: 726 | S6: STO | T6: 6927 | U6: 48.972276 | V6: 52.63371671 | W6: 6585.397 | X6: 46299 | Y6: 46305 | AA6: 31825 | AB6: MAERSK A/S | AC6: CN8245126 | AD6: MERATUS JIMBARAN | AE6: 638N | AF6: CN | AG6: PRT | AH6: CNSHA | AI6: KR | AJ6: KRINC | AK6: PRT | AM6: INVMAEUIK0222603 | AO6: 46307 | AQ6: 한진인천컨테이너터미널(주) | AS6: 신한 | AT6: 46319 | AV6: 46322 | AW6: HANJIN | BC6: HF | BE6: MAEUIK0222603 | BF6: CAJU5753527 | BG6: C40HC | CW6: {=IFERROR(_xlfn.IFS(H6=TIME(7,0,0),"GY",H6=TIME(7,30,0),"GY",H6=TIME(9,0,0),"GY",H6=TIME(15,0,0),"GY",H6=TIME(8,30,0),"GY",H6=TIME(5,30,0),"GY",H6=TIME(6,0,0),"GD",H6=TIME(6,30,0),"GD",H6=TIME(8,0,0),"GY",H6=TIME(6,15,0),"GD"),"")} -> GY
A7: HF | C7: MAEUIK0222603 | D7: CAJU5753527 | E7: C40HC | F7: 277DT260909726620 | G7: 46315 | H7: 0.625 | I7: 46307 | K7: 46305 | L7: 373-STO-S10000031672 | M7: 400 | N7: 258DTS10000203144 | O7: 350 | Q7: 46274 | R7: 726 | S7: STO | T7: 2602 | U7: 6.940198 | V7: 7.441753 | W7: 1068.502 | X7: 46299 | Y7: 46305 | AA7: 31825 | AB7: MAERSK A/S | AC7: CN8245126 | AD7: MERATUS JIMBARAN | AE7: 638N | AF7: CN | AG7: PRT | AH7: CNSHA | AI7: KR | AJ7: KRINC | AK7: PRT | AM7: INVMAEUIK0222603 | AO7: 46307 | AQ7: 한진인천컨테이너터미널(주) | AS7: 신한 | AT7: 46319 | AV7: 46322 | AW7: HANJIN | BC7: HF | BE7: MAEUIK0222603 | BF7: CAJU5753527 | BG7: C40HC | CW7: {=IFERROR(_xlfn.IFS(H7=TIME(7,0,0),"GY",H7=TIME(7,30,0),"GY",H7=TIME(9,0,0),"GY",H7=TIME(15,0,0),"GY",H7=TIME(8,30,0),"GY",H7=TIME(5,30,0),"GY",H7=TIME(6,0,0),"GD",H7=TIME(6,30,0),"GD",H7=TIME(8,0,0),"GY",H7=TIME(6,15,0),"GD"),"")} -> GY
A8: DD | B8: MILK RUN NOR | C8: MAEUIK0222136 | D8: GATU8481853 | E8: C40HC | F8: 21072SUPECIS76085 | G8: 46314 | H8: 0.35416667 | I8: 46307 | K8: 46304 | L8: 373-STO-S10000031632 | M8: 400 | N8: 037TSOS10000698570 | O8: 350 | P8: LINLI65 | Q8: 46271 | R8: 726 | S8: STO | T8: 156 | U8: 4.539972 | V8: 4.841639 | W8: 1999.62 | X8: 46293 | Y8: 46304 | AA8: 31825 | AB8: MAERSK A/S | AC8: CN8989674 | AD8: GJERTRUD MAERSK | AE8: 638E | AF8: CN | AG8: PRT | AH8: CNNGB | AI8: KR | AJ8: KRPUS | AK8: PRT | AM8: INVMAEUIK0222136 | AO8: 46307 | AQ8: 부산신항만(주)자유무역지역 | AR8: MILK RUN NOR | AT8: 46318 | AU8: 46352 | AW8: HANJIN | BC8: DD | BD8: MILK RUN NOR | BE8: MAEUIK0222136 | BF8: GATU8481853 | BG8: C40HC | CW8: {=IFERROR(_xlfn.IFS(H8=TIME(7,0,0),"GY",H8=TIME(7,30,0),"GY",H8=TIME(9,0,0),"GY",H8=TIME(15,0,0),"GY",H8=TIME(8,30,0),"GY",H8=TIME(5,30,0),"GY",H8=TIME(6,0,0),"GD",H8=TIME(6,30,0),"GD",H8=TIME(8,0,0),"GY",H8=TIME(6,15,0),"GD"),"")} -> GY
A9: LF | C9: MAEUIK0221076 | D9: MIEU3937673 | E9: C40HC | F9: 294DT260828726913 | G9: 46314 | H9: 0.27083333 | I9: 46303 | K9: 46300 | L9: 373-STO-S10000031638 | M9: 400 | N9: 258DTS10000201515 | O9: 350 | P9: LARXU | Q9: 46262 | R9: 726 | S9: STO | T9: 11249 | U9: 15.890792 | V9: 17.13080399 | W9: 3153.507 | X9: 46299 | Y9: 46300 | AA9: 31825 | AB9: MAERSK A/S | AC9: CN7277991 | AD9: GSL ELEFTHERIA | AE9: 637N | AF9: CN | AG9: PRT | AH9: CNSHA | AI9: KR | AJ9: KRINC | AK9: PRT | AL9: 한진 | AM9: INVMAEUIK0221076 | AO9: 46303 | AQ9: 한진인천컨테이너터미널(주) | AS9: 신한 | AT9: 46314 | AW9: HANJIN | BC9: LF | BE9: MAEUIK0221076 | BF9: MIEU3937673 | BG9: C40HC | CW9: {=IFERROR(_xlfn.IFS(H9=TIME(7,0,0),"GY",H9=TIME(7,30,0),"GY",H9=TIME(9,0,0),"GY",H9=TIME(15,0,0),"GY",H9=TIME(8,30,0),"GY",H9=TIME(5,30,0),"GY",H9=TIME(6,0,0),"GD",H9=TIME(6,30,0),"GD",H9=TIME(8,0,0),"GY",H9=TIME(6,15,0),"GD"),"")} -> GD
A10: LF | C10: MAEUIK0221076 | D10: MIEU3937673 | E10: C40HC | F10: 319DT260828726914 | G10: 46314 | H10: 0.27083333 | I10: 46303 | K10: 46300 | L10: 373-STO-S10000031638 | M10: 400 | N10: 258DTS10000201515 | O10: 350 | P10: LARXU | Q10: 46262 | R10: 726 | S10: STO | T10: 10034 | U10: 32.237779 | V10: 34.78955881 | W10: 7090.924 | X10: 46299 | Y10: 46300 | AA10: 31825 | AB10: MAERSK A/S | AC10: CN7277991 | AD10: GSL ELEFTHERIA | AE10: 637N | AF10: CN | AG10: PRT | AH10: CNSHA | AI10: KR | AJ10: KRINC | AK10: PRT | AL10: 한진 | AM10: INVMAEUIK0221076 | AO10: 46303 | AQ10: 한진인천컨테이너터미널(주) | AS10: 신한 | AT10: 46314 | AW10: HANJIN | BC10: LF | BE10: MAEUIK0221076 | BF10: MIEU3937673 | BG10: C40HC | CW10: {=IFERROR(_xlfn.IFS(H10=TIME(7,0,0),"GY",H10=TIME(7,30,0),"GY",H10=TIME(9,0,0),"GY",H10=TIME(15,0,0),"GY",H10=TIME(8,30,0),"GY",H10=TIME(5,30,0),"GY",H10=TIME(6,0,0),"GD",H10=TIME(6,30,0),"GD",H10=TIME(8,0,0),"GY",H10=TIME(6,15,0),"GD"),"")} -> GD
A11: DD | B11: MILK RUN NOR | C11: MAEUIK0221730 | D11: MIEU4055031 | E11: C40HC | F11: 21072SUPECIS75985 | G11: 46313 | H11: 0.35416667 | I11: 46307 | K11: 46304 | L11: 373-STO-S10000031603 | M11: 400 | N11: 037TSOS10000696475 | O11: 350 | P11: LINLI65 | Q11: 46268 | R11: 726 | S11: STO | T11: 204 | U11: 5.917482 | V11: 6.312573 | W11: 2962.82 | X11: 46293 | Y11: 46304 | AA11: 31825 | AB11: MAERSK A/S | AC11: CN9083167 | AD11: GJERTRUD MAERSK | AE11: 638E | AF11: CN | AG11: PRT | AH11: CNNGB | AI11: KR | AJ11: KRPUS | AK11: PRT | AM11: INVMAEUIK0221730 | AO11: 46307 | AQ11: 부산신항만(주)자유무역지역 | AR11: MILK RUN NOR | AT11: 46318 | AU11: 46352 | AW11: HANJIN | BC11: DD | BD11: MILK RUN NOR | BE11: MAEUIK0221730 | BF11: MIEU4055031 | BG11: C40HC | CW11: {=IFERROR(_xlfn.IFS(H11=TIME(7,0,0),"GY",H11=TIME(7,30,0),"GY",H11=TIME(9,0,0),"GY",H11=TIME(15,0,0),"GY",H11=TIME(8,30,0),"GY",H11=TIME(5,30,0),"GY",H11=TIME(6,0,0),"GD",H11=TIME(6,30,0),"GD",H11=TIME(8,0,0),"GY",H11=TIME(6,15,0),"GD"),"")} -> GY
A12: HF | C12: MAEUIK0222031 | D12: MIEU4248386 | E12: C40HC | F12: 258DT260904726418 | G12: 46313 | H12: 0.26041667 | I12: 46307 | K12: 46305 | L12: 373-STO-S10000031617 | M12: 400 | N12: 258DTS10000202574 | O12: 350 | Q12: 46269 | R12: 726 | S12: STO | T12: 6394 | U12: 55.448337 | V12: 60.24409681 | W12: 10041.689 | X12: 46298 | Y12: 46305 | AA12: 31825 | AB12: MAERSK A/S | AC12: CN8245186 | AD12: MERATUS JIMBARAN | AE12: 638N | AF12: CN | AG12: PRT | AH12: CNSHA | AI12: KR | AJ12: KRINC | AK12: PRT | AM12: INVMAEUIK0222031 | AO12: 46307 | AQ12: 한진인천컨테이너터미널(주) | AS12: 신한 | AT12: 46319 | AV12: 46322 | AW12: HANJIN | BC12: HF | BE12: MAEUIK0222031 | BF12: MIEU4248386 | BG12: C40HC | CW12: {=IFERROR(_xlfn.IFS(H12=TIME(7,0,0),"GY",H12=TIME(7,30,0),"GY",H12=TIME(9,0,0),"GY",H12=TIME(15,0,0),"GY",H12=TIME(8,30,0),"GY",H12=TIME(5,30,0),"GY",H12=TIME(6,0,0),"GD",H12=TIME(6,30,0),"GD",H12=TIME(8,0,0),"GY",H12=TIME(6,15,0),"GD"),"")} -> GD
A13: DD | B13: MILK RUN NOR | C13: PLISH7H50874 | D13: HLHU8363061 | E13: C40HC | F13: 21072SUPECIS76473 | G13: 46312 | H13: 0.35416667 | I13: 46303 | K13: 46303 | L13: 373-STO-S10000031593 | M13: 400 | N13: 037TSOS10000709772 | O13: 300 | P13: LINLI65 | Q13: 46288 | R13: 726 | S13: STO | T13: 204 | U13: 5.768894 | V13: 6.136606 | W13: 2268.98 | X13: 46304 | Y13: 46302 | AA13: 33300 | AB13: LX PANTOS CO., LTD. | AC13: 123123 | AD13: SAWASDEE SIRIUS | AE13: 2626E | AF13: CN | AG13: PRT | AH13: CNNGB | AI13: KR | AJ13: KRPUS | AK13: PRT | AM13: INVPLISH7H50874 | AO13: 46303 | AQ13: 신선대감만터미널(주) 신선대CY | AR13: MILK RUN NOR | AT13: 46317 | AU13: 46378 | AW13: HANJIN | BC13: DD | BD13: MILK RUN NOR | BE13: PLISH7H50874 | BF13: HLHU8363061 | BG13: C40HC | CW13: {=IFERROR(_xlfn.IFS(H13=TIME(7,0,0),"GY",H13=TIME(7,30,0),"GY",H13=TIME(9,0,0),"GY",H13=TIME(15,0,0),"GY",H13=TIME(8,30,0),"GY",H13=TIME(5,30,0),"GY",H13=TIME(6,0,0),"GD",H13=TIME(6,30,0),"GD",H13=TIME(8,0,0),"GY",H13=TIME(6,15,0),"GD"),"")} -> GY
A14: HF | C14: MAEUIK0221456 | D14: MRKU5905253 | E14: C40HC | F14: 258DT260901726134 | G14: 46312 | H14: 0.26041667 | I14: 46302 | K14: 46300 | L14: 373-STO-S10000031599 | M14: 400 | N14: 258DTS10000201885 | O14: 350 | P14: JEGAO9 | Q14: 46266 | R14: 726 | S14: STO | T14: 7206 | U14: 52.9611 | V14: 56.90923493 | W14: 10466.317 | X14: 46299 | Y14: 46300 | AA14: 31825 | AB14: MAERSK A/S | AC14: CN8117899 | AD14: GSL ELEFTHERIA | AE14: 637N | AF14: CN | AG14: PRT | AH14: CNSHA | AI14: KR | AJ14: KRINC | AK14: PRT | AM14: INVMAEUIK0221456 | AO14: 46302 | AQ14: 한진인천컨테이너터미널(주) | AS14: 신한 | AT14: 46314 | AV14: 46317 | AW14: HANJIN | BC14: HF | BE14: MAEUIK0221456 | BF14: MRKU5905253 | BG14: C40HC | CW14: {=IFERROR(_xlfn.IFS(H14=TIME(7,0,0),"GY",H14=TIME(7,30,0),"GY",H14=TIME(9,0,0),"GY",H14=TIME(15,0,0),"GY",H14=TIME(8,30,0),"GY",H14=TIME(5,30,0),"GY",H14=TIME(6,0,0),"GD",H14=TIME(6,30,0),"GD",H14=TIME(8,0,0),"GY",H14=TIME(6,15,0),"GD"),"")} -> GD
A15: HF | C15: MAEUIK0221456 | D15: MRKU5905253 | E15: C40HC | F15: 258DT260901726136 | G15: 46312 | H15: 0.26041667 | I15: 46302 | K15: 46300 | L15: 373-STO-S10000031599 | M15: 400 | N15: 258DTS10000201885 | O15: 350 | P15: JEGAO9 | Q15: 46266 | R15: 726 | S15: STO | T15: 220 | U15: 2.79726 | V15: 2.985278 | W15: 824.622 | X15: 46299 | Y15: 46300 | AA15: 31825 | AB15: MAERSK A/S | AC15: CN8117899 | AD15: GSL ELEFTHERIA | AE15: 637N | AF15: CN | AG15: PRT | AH15: CNSHA | AI15: KR | AJ15: KRINC | AK15: PRT | AM15: INVMAEUIK0221456 | AO15: 46302 | AQ15: 한진인천컨테이너터미널(주) | AS15: 신한 | AT15: 46314 | AV15: 46317 | AW15: HANJIN | BC15: HF | BE15: MAEUIK0221456 | BF15: MRKU5905253 | BG15: C40HC | CW15: {=IFERROR(_xlfn.IFS(H15=TIME(7,0,0),"GY",H15=TIME(7,30,0),"GY",H15=TIME(9,0,0),"GY",H15=TIME(15,0,0),"GY",H15=TIME(8,30,0),"GY",H15=TIME(5,30,0),"GY",H15=TIME(6,0,0),"GD",H15=TIME(6,30,0),"GD",H15=TIME(8,0,0),"GY",H15=TIME(6,15,0),"GD"),"")} -> GD
A16: HF | C16: MAEUIK0221456 | D16: MRKU5905253 | E16: C40HC | F16: 277DT260901726137 | G16: 46312 | H16: 0.26041667 | I16: 46302 | K16: 46300 | L16: 373-STO-S10000031599 | M16: 400 | N16: 258DTS10000201885 | O16: 350 | P16: JEGAO9 | Q16: 46266 | R16: 726 | S16: STO | T16: 128 | U16: 0.524288 | V16: 0.556875 | W16: 37.76 | X16: 46299 | Y16: 46300 | AA16: 31825 | AB16: MAERSK A/S | AC16: CN8117899 | AD16: GSL ELEFTHERIA | AE16: 637N | AF16: CN | AG16: PRT | AH16: CNSHA | AI16: KR | AJ16: KRINC | AK16: PRT | AM16: INVMAEUIK0221456 | AO16: 46302 | AQ16: 한진인천컨테이너터미널(주) | AS16: 신한 | AT16: 46314 | AV16: 46317 | AW16: HANJIN | BC16: HF | BE16: MAEUIK0221456 | BF16: MRKU5905253 | BG16: C40HC | CW16: {=IFERROR(_xlfn.IFS(H16=TIME(7,0,0),"GY",H16=TIME(7,30,0),"GY",H16=TIME(9,0,0),"GY",H16=TIME(15,0,0),"GY",H16=TIME(8,30,0),"GY",H16=TIME(5,30,0),"GY",H16=TIME(6,0,0),"GD",H16=TIME(6,30,0),"GD",H16=TIME(8,0,0),"GY",H16=TIME(6,15,0),"GD"),"")} -> GD
A17: DD | B17: MILK RUN NOR | C17: MAEUIK0222640 | D17: MIEU4026136 | E17: C40HC | F17: 22715SUPECIS74434 | G17: 46312 | H17: 0.35416667 | I17: 46302 | K17: 46300 | L17: 373-STO-S10000031592 | M17: 400 | N17: 037TSOS10000701591 | O17: 350 | P17: HEDXU | Q17: 46274 | R17: 726 | S17: STO | T17: 130 | U17: 5.51538 | V17: 5.913997 | W17: 2074.79 | X17: 46286 | Y17: 46300 | AA17: 31825 | AB17: MAERSK A/S | AC17: CN8118336 | AD17: GSL ELEFTHERIA | AE17: 637N | AF17: CN | AG17: PRT | AH17: CNSHA | AI17: KR | AJ17: KRINC | AK17: PRT | AM17: INVMAEUIK0222640 | AO17: 46302 | AQ17: 한진인천컨테이너터미널(주) | AS17: 신한 | AT17: 46314 | AV17: 46317 | AW17: HANJIN | BC17: DD | BD17: MILK RUN NOR | BE17: MAEUIK0222640 | BF17: MIEU4026136 | BG17: C40HC | CW17: {=IFERROR(_xlfn.IFS(H17=TIME(7,0,0),"GY",H17=TIME(7,30,0),"GY",H17=TIME(9,0,0),"GY",H17=TIME(15,0,0),"GY",H17=TIME(8,30,0),"GY",H17=TIME(5,30,0),"GY",H17=TIME(6,0,0),"GD",H17=TIME(6,30,0),"GD",H17=TIME(8,0,0),"GY",H17=TIME(6,15,0),"GD"),"")} -> GY
A18: LF | C18: MAEUIK0220633 | D18: MIEU4026408 | E18: C40HC | F18: 294DT260826726667 | G18: 46311 | H18: 0.27083333 | I18: 46302 | K18: 46300 | L18: 373-STO-S10000031572 | M18: 400 | N18: 258DTS10000201056 | O18: 350 | P18: LARXU | Q18: 46260 | R18: 726 | S18: STO | T18: 1324 | U18: 5.167979 | V18: 5.57277518 | W18: 1073.011 | X18: 46299 | Y18: 46300 | AA18: 31825 | AB18: MAERSK A/S | AC18: CN7277908 | AD18: GSL ELEFTHERIA | AE18: 637N | AF18: CN | AG18: PRT | AH18: CNSHA | AI18: KR | AJ18: KRINC | AK18: PRT | AM18: INVMAEUIK0220633 | AO18: 46302 | AQ18: 한진인천컨테이너터미널(주) | AS18: 신한 | AT18: 46314 | AV18: 46317 | AW18: HANJIN | BC18: LF | BE18: MAEUIK0220633 | BF18: MIEU4026408 | BG18: C40HC | CW18: {=IFERROR(_xlfn.IFS(H18=TIME(7,0,0),"GY",H18=TIME(7,30,0),"GY",H18=TIME(9,0,0),"GY",H18=TIME(15,0,0),"GY",H18=TIME(8,30,0),"GY",H18=TIME(5,30,0),"GY",H18=TIME(6,0,0),"GD",H18=TIME(6,30,0),"GD",H18=TIME(8,0,0),"GY",H18=TIME(6,15,0),"GD"),"")} -> GD
A19: LF | C19: MAEUIK0220633 | D19: MIEU4026408 | E19: C40HC | F19: 319DT260826726668 | G19: 46311 | H19: 0.27083333 | I19: 46302 | K19: 46300 | L19: 373-STO-S10000031572 | M19: 400 | N19: 258DTS10000201056 | O19: 350 | P19: LARXU | Q19: 46260 | R19: 726 | S19: STO | T19: 12744 | U19: 43.098395 | V19: 46.33617804 | W19: 7481.412 | X19: 46299 | Y19: 46300 | AA19: 31825 | AB19: MAERSK A/S | AC19: CN7277908 | AD19: GSL ELEFTHERIA | AE19: 637N | AF19: CN | AG19: PRT | AH19: CNSHA | AI19: KR | AJ19: KRINC | AK19: PRT | AM19: INVMAEUIK0220633 | AO19: 46302 | AQ19: 한진인천컨테이너터미널(주) | AS19: 신한 | AT19: 46314 | AV19: 46317 | AW19: HANJIN | BC19: LF | BE19: MAEUIK0220633 | BF19: MIEU4026408 | BG19: C40HC | CW19: {=IFERROR(_xlfn.IFS(H19=TIME(7,0,0),"GY",H19=TIME(7,30,0),"GY",H19=TIME(9,0,0),"GY",H19=TIME(15,0,0),"GY",H19=TIME(8,30,0),"GY",H19=TIME(5,30,0),"GY",H19=TIME(6,0,0),"GD",H19=TIME(6,30,0),"GD",H19=TIME(8,0,0),"GY",H19=TIME(6,15,0),"GD"),"")} -> GD
A20: DD | B20: MILK RUN NOR | C20: MAEUIK0222641 | D20: MIEU4250531 | E20: C40HC | F20: 22715SUPECIS74800 | G20: 46311 | H20: 0.35416667 | I20: 46301 | K20: 46300 | L20: 373-STO-S10000031558 | M20: 400 | N20: 037TSOS10000701589 | O20: 350 | P20: HEDXU | Q20: 46274 | R20: 726 | S20: STO | T20: 284 | U20: 18.975908 | V20: 20.261386 | W20: 8158.02 | X20: 46287 | Y20: 46300 | AA20: 31825 | AB20: MAERSK A/S | AC20: CN8117812 | AD20: GSL ELEFTHERIA | AE20: 637N | AF20: CN | AG20: PRT | AH20: CNSHA | AI20: KR | AJ20: KRINC | AK20: PRT | AM20: INVMAEUIK0222641 | AO20: 46301 | AQ20: 한진인천컨테이너터미널(주) | AS20: 신한 | AT20: 46314 | AV20: 46316 | AW20: HANJIN | BC20: DD | BD20: MILK RUN NOR | BE20: MAEUIK0222641 | BF20: MIEU4250531 | BG20: C40HC | CW20: {=IFERROR(_xlfn.IFS(H20=TIME(7,0,0),"GY",H20=TIME(7,30,0),"GY",H20=TIME(9,0,0),"GY",H20=TIME(15,0,0),"GY",H20=TIME(8,30,0),"GY",H20=TIME(5,30,0),"GY",H20=TIME(6,0,0),"GD",H20=TIME(6,30,0),"GD",H20=TIME(8,0,0),"GY",H20=TIME(6,15,0),"GD"),"")} -> GY
A21: DD | B21: MILK RUN NOR | C21: MAEUIK0220980 | D21: CAAU5980289 | E21: C40HC | F21: 21072SUPECIS75793 | G21: 46310 | H21: 0.35416667 | I21: 46302 | J21: 46301 | K21: 46298 | L21: 373-STO-S10000031553 | M21: 400 | N21: 037TSOS10000692070 | O21: 350 | P21: LINLI65 | Q21: 46261 | R21: 726 | S21: STO | T21: 195 | U21: 6.568349 | V21: 6.98245 | W21: 2702.47 | X21: 46286 | Y21: 46298 | AA21: 31825 | AB21: MAERSK A/S | AC21: CN6570542 | AD21: MUNDRA EXPRESS | AE21: 637E | AF21: CN | AG21: PRT | AH21: CNNGB | AI21: KR | AJ21: KRPUS | AK21: PRT | AM21: INVMAEUIK0220980 | AO21: 46301 | AQ21: 부산신항만(주)자유무역지역 | AR21: MILK RUN NOR, 검사 | AT21: 46312 | AU21: 46347 | AW21: HANJIN | BC21: DD | BD21: MILK RUN NOR | BE21: MAEUIK0220980 | BF21: CAAU5980289 | BG21: C40HC | CW21: {=IFERROR(_xlfn.IFS(H21=TIME(7,0,0),"GY",H21=TIME(7,30,0),"GY",H21=TIME(9,0,0),"GY",H21=TIME(15,0,0),"GY",H21=TIME(8,30,0),"GY",H21=TIME(5,30,0),"GY",H21=TIME(6,0,0),"GD",H21=TIME(6,30,0),"GD",H21=TIME(8,0,0),"GY",H21=TIME(6,15,0),"GD"),"")} -> GY
A22: HF | B22: F/C | C22: MAEUIK0220276 | D22: MRSU2805377 | E22: C40HC | F22: 258DT260824726627 | G22: 46310 | H22: 0.27083333 | I22: 46302 | K22: 46285 | L22: 373-STO-S10000031571 | M22: 400 | N22: 258DTS10000200778 | O22: 350 | Q22: 46258 | R22: 726 | S22: STO | T22: 25043 | U22: 46.062759 | V22: 49.8495584 | W22: 8479.826 | X22: 46271 | Y22: 46285 | AA22: 31825 | AB22: MAERSK A/S | AC22: CN4909050 | AD22: XIN BIN ZHOU | AE22: 635N | AF22: CN | AG22: PRT | AH22: CNSHA | AI22: KR | AJ22: KRINC | AK22: PRT | AM22: INVMAEUIK0220276 | AO22: 46302 | AP22: FINE | AQ22: (주) 화인통상 | AR22: 172차 FOOD CONTACT/10-07 전량 수리 | AS22: 신한 | AW22: HANJIN | BC22: HF | BD22: F/C | BE22: MAEUIK0220276 | BF22: MRSU2805377 | BG22: C40HC | CW22: {=IFERROR(_xlfn.IFS(H22=TIME(7,0,0),"GY",H22=TIME(7,30,0),"GY",H22=TIME(9,0,0),"GY",H22=TIME(15,0,0),"GY",H22=TIME(8,30,0),"GY",H22=TIME(5,30,0),"GY",H22=TIME(6,0,0),"GD",H22=TIME(6,30,0),"GD",H22=TIME(8,0,0),"GY",H22=TIME(6,15,0),"GD"),"")} -> GD
A23: HF | B23: F/C | C23: MAEUIK0220276 | D23: MRSU2805377 | E23: C40HC | F23: 277DT260824726628 | G23: 46310 | H23: 0.27083333 | I23: 46302 | K23: 46285 | L23: 373-STO-S10000031571 | M23: 400 | N23: 258DTS10000200778 | O23: 350 | Q23: 46258 | R23: 726 | S23: STO | T23: 7208 | U23: 8.71888 | V23: 9.364472 | W23: 1703.984 | X23: 46271 | Y23: 46285 | AA23: 31825 | AB23: MAERSK A/S | AC23: CN4909050 | AD23: XIN BIN ZHOU | AE23: 635N | AF23: CN | AG23: PRT | AH23: CNSHA | AI23: KR | AJ23: KRINC | AK23: PRT | AM23: INVMAEUIK0220276 | AO23: 46302 | AP23: FINE | AQ23: (주) 화인통상 | AR23: 172차 FOOD CONTACT/10-07 전량 수리 | AS23: 신한 | AW23: HANJIN | BC23: HF | BD23: F/C | BE23: MAEUIK0220276 | BF23: MRSU2805377 | BG23: C40HC | CW23: {=IFERROR(_xlfn.IFS(H23=TIME(7,0,0),"GY",H23=TIME(7,30,0),"GY",H23=TIME(9,0,0),"GY",H23=TIME(15,0,0),"GY",H23=TIME(8,30,0),"GY",H23=TIME(5,30,0),"GY",H23=TIME(6,0,0),"GD",H23=TIME(6,30,0),"GD",H23=TIME(8,0,0),"GY",H23=TIME(6,15,0),"GD"),"")} -> GD
A24: HF | C24: MAEUIK0222039 | D24: MRKU4820043 | E24: C40HC | F24: 258DT260904726357 | G24: 46309 | H24: 0.27083333 | I24: 46302 | K24: 46300 | L24: 373-STO-S10000031533 | M24: 400 | N24: 258DTS10000202591 | O24: 350 | Q24: 46269 | R24: 726 | S24: STO | T24: 7443 | U24: 51.132604 | V24: 54.87575878 | W24: 5875.985 | X24: 46299 | Y24: 46300 | AA24: 31825 | AB24: MAERSK A/S | AC24: CN8163314 | AD24: GSL ELEFTHERIA | AE24: 637N | AF24: CN | AG24: PRT | AH24: CNSHA | AI24: KR | AJ24: KRINC | AK24: PRT | AM24: INVMAEUIK0222039 | AO24: 46302 | AQ24: 한진인천컨테이너터미널(주) | AS24: 신한 | AT24: 46314 | AV24: 46317 | AW24: HANJIN | BC24: HF | BE24: MAEUIK0222039 | BF24: MRKU4820043 | BG24: C40HC | CW24: {=IFERROR(_xlfn.IFS(H24=TIME(7,0,0),"GY",H24=TIME(7,30,0),"GY",H24=TIME(9,0,0),"GY",H24=TIME(15,0,0),"GY",H24=TIME(8,30,0),"GY",H24=TIME(5,30,0),"GY",H24=TIME(6,0,0),"GD",H24=TIME(6,30,0),"GD",H24=TIME(8,0,0),"GY",H24=TIME(6,15,0),"GD"),"")} -> GD
A25: HF | C25: MAEUIK0222039 | D25: MRKU4820043 | E25: C40HC | F25: 277DT260904726358 | G25: 46309 | H25: 0.27083333 | I25: 46302 | K25: 46300 | L25: 373-STO-S10000031533 | M25: 400 | N25: 258DTS10000202591 | O25: 350 | Q25: 46269 | R25: 726 | S25: STO | T25: 247 | U25: 4.413674 | V25: 4.713329 | W25: 892.138 | X25: 46299 | Y25: 46300 | AA25: 31825 | AB25: MAERSK A/S | AC25: CN8163314 | AD25: GSL ELEFTHERIA | AE25: 637N | AF25: CN | AG25: PRT | AH25: CNSHA | AI25: KR | AJ25: KRINC | AK25: PRT | AM25: INVMAEUIK0222039 | AO25: 46302 | AQ25: 한진인천컨테이너터미널(주) | AS25: 신한 | AT25: 46314 | AV25: 46317 | AW25: HANJIN | BC25: HF | BE25: MAEUIK0222039 | BF25: MRKU4820043 | BG25: C40HC | CW25: {=IFERROR(_xlfn.IFS(H25=TIME(7,0,0),"GY",H25=TIME(7,30,0),"GY",H25=TIME(9,0,0),"GY",H25=TIME(15,0,0),"GY",H25=TIME(8,30,0),"GY",H25=TIME(5,30,0),"GY",H25=TIME(6,0,0),"GD",H25=TIME(6,30,0),"GD",H25=TIME(8,0,0),"GY",H25=TIME(6,15,0),"GD"),"")} -> GD
